<sdf version='1.11'>
  <model name='varuna'>
    <link name='main_body'>
      <inertial>
        <pose>0.0013434676436582639 0.00024462562911645017 -0.0061795086656166072 0 0 0</pose>
        <mass>8.7406916189163084</mass>
        <inertia>
          <ixx>0.090944853636449496</ixx>
          <ixy>2.5456457070889839e-05</ixy>
          <ixz>-0.0020117676796471882</ixz>
          <iyy>0.1765359843345343</iyy>
          <iyz>0.001294728975449389</iyz>
          <izz>0.163107671533855</izz>
        </inertia>
      </inertial>
      <collision name='main_body_collision'>
        <pose>0 0 0 0 0 0</pose>
        <geometry>
          <mesh>
            <scale>1 1 1</scale>
            <uri>model://varuna/meshes/main_body.STL</uri>
          </mesh>
        </geometry>
      </collision>
      <collision name='main_body_fixed_joint_lump__bottom_camera_link_collision_1'>
        <pose>-0.000161955480955045 -0.098296309574883903 0.14604807484961399 -1.5707963267949003 -5.5511151231257827e-17 -1.5707963267949003</pose>
        <geometry>
          <mesh>
            <scale>1 1 1</scale>
            <uri>model://varuna/meshes/bottom_camera_link.STL</uri>
          </mesh>
        </geometry>
        <surface>
          <contact>
            <ode/>
          </contact>
          <friction>
            <ode/>
          </friction>
        </surface>
      </collision>
      <collision name='main_body_fixed_joint_lump__front_camera_link_collision_2'>
        <pose>0.29049000000000003 -0.00032538000000000001 0.087131 -1.5708 -5.5511151231257827e-17 -1.5708</pose>
        <geometry>
          <mesh>
            <scale>1 1 1</scale>
            <uri>model://varuna/meshes/front_camera_link.STL</uri>
          </mesh>
        </geometry>
        <surface>
          <contact>
            <ode/>
          </contact>
          <friction>
            <ode/>
          </friction>
        </surface>
      </collision>
      <visual name='main_body_visual'>
        <pose>0 0 0 0 0 0</pose>
        <geometry>
          <mesh>
            <scale>1 1 1</scale>
            <uri>model://varuna/meshes/main_body.STL</uri>
          </mesh>
        </geometry>
        <material>
          <diffuse>1 1 1 0.349999994</diffuse>
          <ambient>1 1 1 0.349999994</ambient>
        </material>
      </visual>
      <visual name='main_body_fixed_joint_lump__bottom_camera_link_visual_1'>
        <pose>-0.000161955480955045 -0.098296309574883903 0.14604807484961399 -1.5707963267949003 -5.5511151231257827e-17 -1.5707963267949003</pose>
        <geometry>
          <mesh>
            <scale>1 1 1</scale>
            <uri>model://varuna/meshes/bottom_camera_link.STL</uri>
          </mesh>
        </geometry>
        <material>
          <diffuse>0 0 1 1</diffuse>
          <ambient>0 0 1 1</ambient>
        </material>
      </visual>
      <visual name='main_body_fixed_joint_lump__front_camera_link_visual_2'>
        <pose>0.29049000000000003 -0.00032538000000000001 0.087131 -1.5708 -5.5511151231257827e-17 -1.5708</pose>
        <geometry>
          <mesh>
            <scale>1 1 1</scale>
            <uri>model://varuna/meshes/front_camera_link.STL</uri>
          </mesh>
        </geometry>
        <material>
          <diffuse>1 0 0 1</diffuse>
          <ambient>1 0 0 1</ambient>
        </material>
      </visual>
      <sensor name='bottom_camera' type='camera'>
        <camera>
          <horizontal_fov>1.9550000000000001</horizontal_fov>
          <image>
            <width>1280</width>
            <height>720</height>
          </image>
          <clip>
            <near>0.10000000000000001</near>
            <far>30</far>
          </clip>
        </camera>
        <always_on>true</always_on>
        <update_rate>30</update_rate>
        <topic>/bottom/image_raw</topic>
        <pose>-0.000161955 -0.098296300000000003 0.14604800000000001 -1.5708 -5.5511151231257827e-17 -1.5708</pose>
      </sensor>
      <sensor name='front_camera' type='camera'>
        <camera>
          <horizontal_fov>1.3089999999999999</horizontal_fov>
          <image>
            <width>1280</width>
            <height>720</height>
          </image>
          <clip>
            <near>0.10000000000000001</near>
            <far>30</far>
          </clip>
        </camera>
        <always_on>true</always_on>
        <update_rate>30</update_rate>
        <visualize>true</visualize>
        <topic>/front_left/image_raw</topic>
        <pose>0.29049000000000003 -0.00032538000000000001 0.087131 -1.5708 -5.5511151231257827e-17 -1.5708</pose>
      </sensor>
      <sensor name='imu_sensor' type='imu'>
        <always_on>true</always_on>
        <update_rate>100</update_rate>
        <topic>/demo/imu</topic>
        <plugin name='ignition::gazebo::systems::Imu' filename='ignition-gazebo-imu-system'/>
        <pose>0 0 0 0 0 0</pose>
        <imu/>
      </sensor>
    </link>
    <joint name='back_left_joint' type='revolute'>
      <pose relative_to='main_body'>-0.23288 -0.16011 0.030787999999999999 -1.5708 -5.5511151231257827e-17 -1.5708</pose>
      <parent>main_body</parent>
      <child>back_left_thrust</child>
      <axis>
        <xyz>0 1 0</xyz>
        <limit>
          <lower>-1000000000000</lower>
          <upper>1000000000000</upper>
          <effort>-1</effort>
          <velocity>-1</velocity>
        </limit>
        <dynamics>
          <spring_reference>0</spring_reference>
          <spring_stiffness>0</spring_stiffness>
        </dynamics>
      </axis>
    </joint>
    <link name='back_left_thrust'>
      <pose relative_to='back_left_joint'>0 0 0 0 0 0</pose>
      <inertial>
        <pose>0.0092488801059882903 0.0077405991828577003 -0.0031298765738126798 0 0 0</pose>
        <mass>0.237469836698007</mass>
        <inertia>
          <ixx>0.00018446857162333601</ixx>
          <ixy>8.1429979512563805e-09</ixy>
          <ixz>-3.3750301534730501e-05</ixz>
          <iyy>0.00026132180932715701</iyy>
          <iyz>-1.6694137053982501e-07</iyz>
          <izz>0.00016390459744937801</izz>
        </inertia>
      </inertial>
      <collision name='back_left_thrust_collision'>
        <pose>0 0 0 0 0 0</pose>
        <geometry>
          <mesh>
            <scale>1 1 1</scale>
            <uri>model://varuna/meshes/back_left_thrust.STL</uri>
          </mesh>
        </geometry>
      </collision>
      <visual name='back_left_thrust_visual'>
        <pose>0 0 0 0 0 0</pose>
        <geometry>
          <mesh>
            <scale>1 1 1</scale>
            <uri>model://varuna/meshes/back_left_thrust.STL</uri>
          </mesh>
        </geometry>
        <material>
          <diffuse>0.313725501 0.313725501 0.313725501 1</diffuse>
          <ambient>0.313725501 0.313725501 0.313725501 1</ambient>
        </material>
      </visual>
    </link>
    <joint name='back_right_joint' type='revolute'>
      <pose relative_to='main_body'>-0.23288 0.15945999999999999 0.030787999999999999 -1.5708 -5.5511151231257827e-17 -1.5708</pose>
      <parent>main_body</parent>
      <child>back_right_thrust</child>
      <axis>
        <xyz>0 1 0</xyz>
        <limit>
          <lower>-1000000000000</lower>
          <upper>1000000000000</upper>
          <effort>-1</effort>
          <velocity>-1</velocity>
        </limit>
        <dynamics>
          <spring_reference>0</spring_reference>
          <spring_stiffness>0</spring_stiffness>
        </dynamics>
      </axis>
    </joint>
    <link name='back_right_thrust'>
      <pose relative_to='back_right_joint'>0 0 0 0 0 0</pose>
      <inertial>
        <pose>-0.0091907215631215709 0.0077406004871417699 -0.0031813216755611599 0 0 0</pose>
        <mass>0.23746984384368</mass>
        <inertia>
          <ixx>0.000184602036093544</ixx>
          <ixy>-1.88322406575791e-07</ixy>
          <ixz>3.3766709684067502e-05</ixz>
          <iyy>0.00026132181742654801</iyy>
          <iyz>-5.5165622356500502e-08</iyz>
          <izz>0.000163771149198568</izz>
        </inertia>
      </inertial>
      <collision name='back_right_thrust_collision'>
        <pose>0 0 0 0 0 0</pose>
        <geometry>
          <mesh>
            <scale>1 1 1</scale>
            <uri>model://varuna/meshes/back_right_thrust.STL</uri>
          </mesh>
        </geometry>
      </collision>
      <visual name='back_right_thrust_visual'>
        <pose>0 0 0 0 0 0</pose>
        <geometry>
          <mesh>
            <scale>1 1 1</scale>
            <uri>model://varuna/meshes/back_right_thrust.STL</uri>
          </mesh>
        </geometry>
        <material>
          <diffuse>0.990196109 1 1 1</diffuse>
          <ambient>0.990196109 1 1 1</ambient>
        </material>
      </visual>
    </link>
    <joint name='front_left_joint' type='revolute'>
      <pose relative_to='main_body'>0.23086000000000001 -0.16011 0.030787999999999999 -1.5708 -5.5511151231257827e-17 -1.5708</pose>
      <parent>main_body</parent>
      <child>front_left_thrust</child>
      <axis>
        <xyz>0 1 0</xyz>
        <limit>
          <lower>-1000000000000</lower>
          <upper>1000000000000</upper>
          <effort>-1</effort>
          <velocity>-1</velocity>
        </limit>
        <dynamics>
          <spring_reference>0</spring_reference>
          <spring_stiffness>0</spring_stiffness>
        </dynamics>
      </axis>
    </joint>
    <link name='front_left_thrust'>
      <pose relative_to='front_left_joint'>0 0 0 0 0 0</pose>
      <inertial>
        <pose>0.00919072238475643 0.0077405986401891296 0.0031813215745006801 0 0 0</pose>
        <mass>0.23746985311449501</mass>
        <inertia>
          <ixx>0.00018460204577230201</ixx>
          <ixy>1.8833050661776501e-07</ixy>
          <ixz>3.3766711381648299e-05</ixz>
          <iyy>0.00026132182182160801</iyy>
          <iyz>5.5159998099329097e-08</iyz>
          <izz>0.000163771165503046</izz>
        </inertia>
      </inertial>
      <collision name='front_left_thrust_collision'>
        <pose>0 0 0 0 0 0</pose>
        <geometry>
          <mesh>
            <scale>1 1 1</scale>
            <uri>model://varuna/meshes/front_left_thrust.STL</uri>
          </mesh>
        </geometry>
      </collision>
      <visual name='front_left_thrust_visual'>
        <pose>0 0 0 0 0 0</pose>
        <geometry>
          <mesh>
            <scale>1 1 1</scale>
            <uri>model://varuna/meshes/front_left_thrust.STL</uri>
          </mesh>
        </geometry>
        <material>
          <diffuse>0.990196109 1 1 1</diffuse>
          <ambient>0.990196109 1 1 1</ambient>
        </material>
      </visual>
    </link>
    <joint name='front_right_joint' type='revolute'>
      <pose relative_to='main_body'>0.23086000000000001 0.15945999999999999 0.030787999999999999 -1.5708 -5.5511151231257827e-17 -1.5708</pose>
      <parent>main_body</parent>
      <child>front_right_thrust</child>
      <axis>
        <xyz>0 1 0</xyz>
        <limit>
          <lower>-1000000000000</lower>
          <upper>1000000000000</upper>
          <effort>-1</effort>
          <velocity>-1</velocity>
        </limit>
        <dynamics>
          <spring_reference>0</spring_reference>
          <spring_stiffness>0</spring_stiffness>
        </dynamics>
      </axis>
    </joint>
    <link name='front_right_thrust'>
      <pose relative_to='front_right_joint'>0 0 0 0 0 0</pose>
      <inertial>
        <pose>-0.0092488800092467693 0.0077405991332517203 0.0031298764817926398 0 0 0</pose>
        <mass>0.23746983749838299</mass>
        <inertia>
          <ixx>0.000184468577429034</ixx>
          <ixy>-8.1410508915737903e-09</ixy>
          <ixz>-3.37503020099821e-05</ixz>
          <iyy>0.00026132181144024802</iyy>
          <iyz>1.6694295560257499e-07</iyz>
          <izz>0.00016390460326347301</izz>
        </inertia>
      </inertial>
      <collision name='front_right_thrust_collision'>
        <pose>0 0 0 0 0 0</pose>
        <geometry>
          <mesh>
            <scale>1 1 1</scale>
            <uri>model://varuna/meshes/front_right_thrust.STL</uri>
          </mesh>
        </geometry>
      </collision>
      <visual name='front_right_thrust_visual'>
        <pose>0 0 0 0 0 0</pose>
        <geometry>
          <mesh>
            <scale>1 1 1</scale>
            <uri>model://varuna/meshes/front_right_thrust.STL</uri>
          </mesh>
        </geometry>
        <material>
          <diffuse>0.990196109 1 1 1</diffuse>
          <ambient>0.990196109 1 1 1</ambient>
        </material>
      </visual>
    </link>
    <joint name='surge_left_joint' type='revolute'>
      <pose relative_to='main_body'>-0.0026267 -0.15731999999999999 -0.0061685000000000004 -1.5708 -5.5511151231257827e-17 -1.5708</pose>
      <parent>main_body</parent>
      <child>surge_left_thrust</child>
      <axis>
        <xyz>0 0 -1</xyz>
        <limit>
          <lower>-1000000000000</lower>
          <upper>1000000000000</upper>
          <effort>-1</effort>
          <velocity>-1</velocity>
        </limit>
        <dynamics>
          <spring_reference>0</spring_reference>
          <spring_stiffness>0</spring_stiffness>
        </dynamics>
      </axis>
    </joint>
    <link name='surge_left_thrust'>
      <pose relative_to='surge_left_joint'>0 0 0 0 0 0</pose>
      <inertial>
        <pose>0.0044132320410271699 -8.5331396670884596e-09 0.00014804231510018301 0 0 0</pose>
        <mass>2.3330914658672799</mass>
        <inertia>
          <ixx>0.0032669773266240901</ixx>
          <ixy>-2.5025168669193301e-09</ixy>
          <ixz>-6.0522854482407998e-06</ixz>
          <iyy>0.0036995845914223001</iyy>
          <iyz>-3.5309588038680898e-11</iyz>
          <izz>0.00255837495631853</izz>
        </inertia>
      </inertial>
      <collision name='surge_left_thrust_collision'>
        <pose>0 0 0 0 0 0</pose>
        <geometry>
          <mesh>
            <scale>1 1 1</scale>
            <uri>model://varuna/meshes/surge_left_thrust.STL</uri>
          </mesh>
        </geometry>
      </collision>
      <visual name='surge_left_thrust_visual'>
        <pose>0 0 0 0 0 0</pose>
        <geometry>
          <mesh>
            <scale>1 1 1</scale>
            <uri>model://varuna/meshes/surge_left_thrust.STL</uri>
          </mesh>
        </geometry>
        <material>
          <diffuse>1 1 1 1</diffuse>
          <ambient>1 1 1 1</ambient>
        </material>
      </visual>
    </link>
    <joint name='surge_right_joint' type='revolute'>
      <pose relative_to='main_body'>-0.0026231000000000002 0.15668000000000001 -0.0061678999999999996 -1.5708 -5.5511151231257827e-17 -1.5708</pose>
      <parent>main_body</parent>
      <child>surge_right_thrust</child>
      <axis>
        <xyz>0 -0.00036980999999999998 -1</xyz>
        <limit>
          <lower>-1000000000000</lower>
          <upper>1000000000000</upper>
          <effort>-1</effort>
          <velocity>-1</velocity>
        </limit>
        <dynamics>
          <spring_reference>0</spring_reference>
          <spring_stiffness>0</spring_stiffness>
        </dynamics>
      </axis>
    </joint>
    <link name='surge_right_thrust'>
      <pose relative_to='surge_right_joint'>0 0 0 0 0 0</pose>
      <inertial>
        <pose>-0.0044131460192868097 6.5664343018578806e-08 0.000148042274560944 0 0 0</pose>
        <mass>2.3330915408895501</mass>
        <inertia>
          <ixx>0.00326697736792286</ixx>
          <ixy>-2.53182221829006e-10</ixy>
          <ixz>6.0544283536992899e-06</ixz>
          <iyy>0.0036995844218722499</iyy>
          <iyz>-4.2199879882419803e-07</iyz>
          <izz>0.0025583751359115098</izz>
        </inertia>
      </inertial>
      <collision name='surge_right_thrust_collision'>
        <pose>0 0 0 0 0 0</pose>
        <geometry>
          <mesh>
            <scale>1 1 1</scale>
            <uri>model://varuna/meshes/surge_right_thrust.STL</uri>
          </mesh>
        </geometry>
      </collision>
      <visual name='surge_right_thrust_visual'>
        <pose>0 0 0 0 0 0</pose>
        <geometry>
          <mesh>
            <scale>1 1 1</scale>
            <uri>model://varuna/meshes/surge_right_thrust.STL</uri>
          </mesh>
        </geometry>
        <material>
          <diffuse>1 1 1 1</diffuse>
          <ambient>1 1 1 1</ambient>
        </material>
      </visual>
    </link>
    <joint name='sway_back_joint' type='revolute'>
      <pose relative_to='main_body'>-0.14484 0.0096085000000000007 0.12117 -1.5708 -5.5511151231257827e-17 -1.5708</pose>
      <parent>main_body</parent>
      <child>sway_back_thrust</child>
      <axis>
        <xyz>1 0 0</xyz>
        <limit>
          <lower>-1000000000000</lower>
          <upper>1000000000000</upper>
          <effort>-1</effort>
          <velocity>-1</velocity>
        </limit>
        <dynamics>
          <spring_reference>0</spring_reference>
          <spring_stiffness>0</spring_stiffness>
        </dynamics>
      </axis>
    </joint>
    <link name='sway_back_thrust'>
      <pose relative_to='sway_back_joint'>0 0 0 0 0 0</pose>
      <inertial>
        <pose>0.00142695277405866 -7.9187460975960199e-07 -0.0032853268140359002 0 0 0</pose>
        <mass>0.19819796374712301</mass>
        <inertia>
          <ixx>0.00018039109182722</ixx>
          <ixy>-4.0738269212196097e-09</ixy>
          <ixz>3.0257373704744803e-07</ixz>
          <iyy>0.000134875055612333</iyy>
          <iyz>7.2071377900833795e-08</iyz>
          <izz>0.00013134331564052901</izz>
        </inertia>
      </inertial>
      <collision name='sway_back_thrust_collision'>
        <pose>0 0 0 0 0 0</pose>
        <geometry>
          <mesh>
            <scale>1 1 1</scale>
            <uri>model://varuna/meshes/sway_back_thrust.STL</uri>
          </mesh>
        </geometry>
      </collision>
      <visual name='sway_back_thrust_visual'>
        <pose>0 0 0 0 0 0</pose>
        <geometry>
          <mesh>
            <scale>1 1 1</scale>
            <uri>model://varuna/meshes/sway_back_thrust.STL</uri>
          </mesh>
        </geometry>
        <material>
          <diffuse>0 0 1 1</diffuse>
          <ambient>0 0 1 1</ambient>
        </material>
      </visual>
    </link>
    <joint name='sway_thrust_joint' type='revolute'>
      <pose relative_to='main_body'>0.13444 -0.010255999999999999 0.11287999999999999 -1.5708 -5.5511151231257827e-17 -1.5708</pose>
      <parent>main_body</parent>
      <child>sway_front_thrust</child>
      <axis>
        <xyz>-1 0 0</xyz>
        <limit>
          <lower>-1000000000000</lower>
          <upper>1000000000000</upper>
          <effort>-1</effort>
          <velocity>-1</velocity>
        </limit>
        <dynamics>
          <spring_reference>0</spring_reference>
          <spring_stiffness>0</spring_stiffness>
        </dynamics>
      </axis>
    </joint>
    <link name='sway_front_thrust'>
      <pose relative_to='sway_thrust_joint'>0 0 0 0 0 0</pose>
      <inertial>
        <pose>-0.0014269527739064201 -7.9187724555049299e-07 0.0032853268196918499 0 0 0</pose>
        <mass>0.19819796375293899</mass>
        <inertia>
          <ixx>0.00018039109137781299</ixx>
          <ixy>4.0744117192494403e-09</ixy>
          <ixz>3.0257369126354402e-07</ixz>
          <iyy>0.000134875054424953</iyy>
          <iyz>-7.2071420037739803e-08</iyz>
          <izz>0.00013134331420312499</izz>
        </inertia>
      </inertial>
      <collision name='sway_front_thrust_collision'>
        <pose>0 0 0 0 0 0</pose>
        <geometry>
          <mesh>
            <scale>1 1 1</scale>
            <uri>model://varuna/meshes/sway_front_thrust.STL</uri>
          </mesh>
        </geometry>
      </collision>
      <visual name='sway_front_thrust_visual'>
        <pose>0 0 0 0 0 0</pose>
        <geometry>
          <mesh>
            <scale>1 1 1</scale>
            <uri>model://varuna/meshes/sway_front_thrust.STL</uri>
          </mesh>
        </geometry>
        <material>
          <diffuse>0.990196109 1 1 1</diffuse>
          <ambient>0.990196109 1 1 1</ambient>
        </material>
      </visual>
    </link>
    <plugin name='ignition::gazebo::systems::Hydrodynamics' filename='ignition-gazebo-hydrodynamics-system'>
      <link_name>main_body</link_name>
      <water_density>1000</water_density>
      <xDotU>0</xDotU>
      <yDotV>0</yDotV>
      <zDotW>0</zDotW>
      <kDotP>0</kDotP>
      <mDotQ>0</mDotQ>
      <nDotR>0</nDotR>
      <xU>-33.8</xU>
      <yV>-54.2</yV>
      <zW>-73.3</zW>
      <kP>-4.0</kP>
      <mQ>-4.0</mQ>
      <nR>-4.0</nR>
    </plugin>
    <plugin name='ignition::gazebo::systems::Thruster' filename='ignition-gazebo-thruster-system'>
      <namespace>varuna</namespace>
      <joint_name>front_right_joint</joint_name>
      <thrust_coefficient>0.02</thrust_coefficient>
      <fluid_density>1000</fluid_density>
      <propeller_diameter>0.1</propeller_diameter>
      <velocity_control>true</velocity_control>
      <use_angvel_cmd>True</use_angvel_cmd>
    </plugin>
    <plugin name='ignition::gazebo::systems::Thruster' filename='ignition-gazebo-thruster-system'>
      <namespace>varuna</namespace>
      <joint_name>front_left_joint</joint_name>
      <thrust_coefficient>0.02</thrust_coefficient>
      <fluid_density>1000</fluid_density>
      <propeller_diameter>0.1</propeller_diameter>
      <velocity_control>true</velocity_control>
      <use_angvel_cmd>True</use_angvel_cmd>
    </plugin>
    <plugin name='ignition::gazebo::systems::Thruster' filename='ignition-gazebo-thruster-system'>
      <namespace>varuna</namespace>
      <joint_name>back_right_joint</joint_name>
      <thrust_coefficient>-0.02</thrust_coefficient>
      <fluid_density>1000</fluid_density>
      <propeller_diameter>0.1</propeller_diameter>
      <velocity_control>true</velocity_control>
      <use_angvel_cmd>True</use_angvel_cmd>
    </plugin>
    <plugin name='ignition::gazebo::systems::Thruster' filename='ignition-gazebo-thruster-system'>
      <namespace>varuna</namespace>
      <joint_name>back_left_joint</joint_name>
      <thrust_coefficient>-0.02</thrust_coefficient>
      <fluid_density>1000</fluid_density>
      <propeller_diameter>0.1</propeller_diameter>
      <velocity_control>true</velocity_control>
      <use_angvel_cmd>True</use_angvel_cmd>
    </plugin>
    <plugin name='ignition::gazebo::systems::Thruster' filename='ignition-gazebo-thruster-system'>
      <namespace>varuna</namespace>
      <joint_name>surge_right_joint</joint_name>
      <thrust_coefficient>0.02</thrust_coefficient>
      <fluid_density>1000</fluid_density>
      <propeller_diameter>0.1</propeller_diameter>
      <velocity_control>true</velocity_control>
      <use_angvel_cmd>True</use_angvel_cmd>
    </plugin>
    <plugin name='ignition::gazebo::systems::Thruster' filename='ignition-gazebo-thruster-system'>
      <namespace>varuna</namespace>
      <joint_name>surge_left_joint</joint_name>
      <thrust_coefficient>-0.02</thrust_coefficient>
      <fluid_density>1000</fluid_density>
      <propeller_diameter>0.1</propeller_diameter>
      <velocity_control>true</velocity_control>
      <use_angvel_cmd>True</use_angvel_cmd>
    </plugin>
    <plugin name='ignition::gazebo::systems::Thruster' filename='ignition-gazebo-thruster-system'>
      <namespace>varuna</namespace>
      <joint_name>sway_thrust_joint</joint_name>
      <thrust_coefficient>0.02</thrust_coefficient>
      <fluid_density>1000</fluid_density>
      <propeller_diameter>0.1</propeller_diameter>
      <velocity_control>true</velocity_control>
      <use_angvel_cmd>True</use_angvel_cmd>
    </plugin>
    <plugin name='ignition::gazebo::systems::Thruster' filename='ignition-gazebo-thruster-system'>
      <namespace>varuna</namespace>
      <joint_name>sway_back_joint</joint_name>
      <thrust_coefficient>-0.02</thrust_coefficient>
      <fluid_density>1000</fluid_density>
      <propeller_diameter>0.1</propeller_diameter>
      <velocity_control>true</velocity_control>
      <use_angvel_cmd>True</use_angvel_cmd>
    </plugin>
    <plugin name='ignition::gazebo::systems::OdometryPublisher' filename='ignition-gazebo-odometry-publisher-system'>
      <link_name>main_body</link_name>
      <odom_publish_topic>/odom</odom_publish_topic>
      <frame_id>odom</frame_id>
      <child_frame_id>base_link</child_frame_id>
      <publish_tf>true</publish_tf>
    </plugin>
    <frame name='bottom_camera_joint' attached_to='main_body'>
      <pose>-0.000161955480955045 -0.098296309574883903 0.14604807484961399 -1.5707963267949003 -5.5511151231257827e-17 -1.5707963267949003</pose>
    </frame>
    <frame name='bottom_camera_link' attached_to='bottom_camera_joint'>
      <pose>0 0 0 0 0 0</pose>
    </frame>
    <frame name='front_camera_joint' attached_to='main_body'>
      <pose>0.29049000000000003 -0.00032538000000000001 0.087131 -1.5708 -5.5511151231257827e-17 -1.5708</pose>
    </frame>
    <frame name='front_camera_link' attached_to='front_camera_joint'>
      <pose>0 0 0 0 0 0</pose>
    </frame>
    <frame name='imu_joint' attached_to='main_body'>
      <pose>0 0 0 0 0 0</pose>
    </frame>
    <frame name='imu_link' attached_to='imu_joint'>
      <pose>0 0 0 0 0 0</pose>
    </frame>
  </model>
</sdf>
