<?xml version='1.0'?>
<robot name="orca4_ign" xmlns:xacro="http://ros.org/wiki/xacro">
    <origin xyz="0 0 0" rpy="0 0 0"/>

    <!-- BlueROV2 thruster reference: http://www.ardusub.com/introduction/features.html -->
    <!-- fluid_density: 1000 -->
    <!-- displaced_mass: 10.05 -->

    <link name="base_link">
      <inertial>
        <origin xyz="0 0 0.011" rpy="0 0 0"/>
        <mass value="10.036"/>
        <inertia ixx="0.09873097998042396" ixy="0.0" ixz="0.0" iyy="0.17756847998042397" iyz="0.0" izz="0.2692441666666667"/>
      </inertial>

      <visual name="base_link_visual">
        <geometry>
          <mesh filename="package://auv_slam/models/orca4_ign/meshes/bluerov2.dae" scale = "0.025 0.025 0.025"/>
        </geometry>
      </visual>

      <!-- Collision volume * fluid_density == displaced mass, used by BuoyancyPlugin -->
      <collision name="base_link_collision">
        <origin xyz="0 0 0.06" rpy="0 0 0"/>
        <geometry>
          <box size = "0.457 0.338 0.06506286173008947"/>
        </geometry>
      </collision>

    </link>

    <!-- Hydrodynamics plugin -->
    <gazebo>
    <plugin
        filename="ignition-gazebo-hydrodynamics-system"
        name="ignition::gazebo::systems::Hydrodynamics">
      <link_name>base_link</link_name>
      <water_density>1000</water_density>
      <!-- Added mass: -->
      <xDotU>0</xDotU>
      <yDotV>0</yDotV>
      <zDotW>0</zDotW>
      <kDotP>0</kDotP>
      <mDotQ>0</mDotQ>
      <nDotR>0</nDotR>
      <!-- First order stability derivative: -->
      <xU>0</xU>
      <yV>0</yV>
      <zW>0</zW>
      <kP>0</kP>
      <mQ>0</mQ>
      <nR>0</nR>
      <!-- Second order stability derivative: -->
      <xUabsU>-33.800000000000004</xUabsU>
      <yVabsV>-54.26875</yVabsV>
      <zWabsW>-73.37135</zWabsW>
      <kPabsP>-4.0</kPabsP>
      <mQabsQ>-4.0</mQabsQ>
      <nRabsR>-4.0</nRabsR>
    </plugin>
    </gazebo>

    <link name="thruster1">
      <visual name="thruster_prop_visual">
        <origin xyz="0 0 0" rpy="1.5707963267948966 0 0"/>
        <geometry>
          <mesh filename="package://auv_slam/models/orca4_ign/meshes/t200-cw-prop.dae"/>
        </geometry>
      </visual>
      <inertial>
        <mass value="0.002"/>
        <inertia ixx="0.001" ixy="0.0" ixz="0.0" iyy="0.001" iyz="0.0" izz="0.001" />
      </inertial>
    </link>

    <link name="thruster2">
      <origin xyz="0.14 0.092 0" rpy="-1.5707963267948966 1.5707963267948966 -2.356194490192345"/>
      <visual name="thruster_prop_visual">
        <origin xyz="0 0 0" rpy="1.5707963267948966 0 0"/>
        <geometry>
          <mesh filename="package://auv_slam/models/orca4_ign/meshes/t200-ccw-prop.dae"/>
        </geometry>
      </visual>
      <inertial>
        <mass value="0.002"/>
        <inertia ixx="0.001" ixy="0.0" ixz="0.0" iyy="0.001" iyz="0.0" izz="0.001" />
      </inertial>
    </link>

    <link name="thruster3">
      <origin xyz="-0.14 -0.092 0" rpy="-1.5707963267948966 1.5707963267948966 0.7853981633974483"/>
      <visual name="thruster_prop_visual">
        <origin xyz="0 0 0" rpy="-1.5707963267948966 0 0"/>
        <geometry>
          <mesh filename="package://auv_slam/models/orca4_ign/meshes/t200-ccw-prop.dae"/>
        </geometry>
      </visual>
      <inertial>
        <mass value="0.002"/>
        <inertia ixx="0.001" ixy="0.0" ixz="0.0" iyy="0.001" iyz="0.0" izz="0.001" />
      </inertial>
    </link>

    <link name="thruster4">
      <origin xyz="-0.14 0.092 0" rpy="-1.5707963267948966 1.5707963267948966 2.356194490192345"/>
      <visual name="thruster_prop_visual">
        <origin xyz="0 0 0" rpy="1.5707963267948966 0 0"/>
        <geometry>
          <mesh filename="package://auv_slam/models/orca4_ign/meshes/t200-cw-prop.dae"/>
        </geometry>
      </visual>
      <inertial>
        <mass value="0.002"/>
        <inertia ixx="0.001" ixy="0.0" ixz="0.0" iyy="0.001" iyz="0.0" izz="0.001" />
      </inertial>
    </link>

    <link name="thruster5">
      <origin xyz="0 -0.109 0.077" rpy="0 0 0"/>
      <visual name="thruster_prop_visual">
        <origin xyz="0 0 0" rpy="-1.5707963267948966 0 1.5707963267948966"/>
        <geometry>
          <mesh filename="package://auv_slam/models/orca4_ign/meshes/t200-ccw-prop.dae"/>
        </geometry>
      </visual>
      <inertial>
        <mass value="0.002"/>
        <inertia ixx="0.001" ixy="0.0" ixz="0.0" iyy="0.001" iyz="0.0" izz="0.001" />
      </inertial>
    </link>

    <link name="thruster6">
      <origin xyz="0 0.109 0.077" rpy="0 0 0"/>
      <visual name="thruster_prop_visual">
        <origin xyz="0 0 0" rpy="1.5707963267948966 0 1.5707963267948966"/>
        <geometry>
          <mesh filename="package://auv_slam/models/orca4_ign/meshes/t200-cw-prop.dae"/>
        </geometry>
      </visual>
      <inertial>
        <mass value="0.002"/>
        <inertia ixx="0.001" ixy="0.0" ixz="0.0" iyy="0.001" iyz="0.0" izz="0.001" />
      </inertial>
    </link>


    <joint name="thruster1_joint" type="revolute">
    <parent link="base_link" />
    <child link="thruster1" />
    <origin xyz="0.14 -0.092 0" rpy="0 0 -0.7853981633974483"/>
    <axis xyz="1 0 0" />  <!-- CRITICAL FIX: Changed from "0 0 -1" -->
    <limit lower="-1e+12" upper="1e+12" effort="-1" velocity="-1"/>
  </joint>

  <!-- Thruster 2: Front-Right (45° angle, facing forward-right) -->
  <joint name="thruster2_joint" type="revolute">
    <parent link="base_link" />
    <child link="thruster2" />
    <origin xyz="0.14 0.092 0" rpy="0 0 -2.356194490192345"/>
    <axis xyz="1 0 0" />  <!-- CRITICAL FIX: Changed from "0 0 -1" -->
    <limit lower="-1e+12" upper="1e+12" effort="-1" velocity="-1"/>
  </joint>

  <!-- Thruster 3: Back-Left (45° angle, facing backward-left) -->
  <joint name="thruster3_joint" type="revolute">
    <parent link="base_link" />
    <child link="thruster3" />
    <origin xyz="-0.14 -0.092 0" rpy="0 0 0.7853981633974483"/>
    <axis xyz="1 0 0" />  <!-- CRITICAL FIX: Changed from "0 0 -1" -->
    <limit lower="-1e+12" upper="1e+12" effort="-1" velocity="-1"/>
  </joint>

  <!-- Thruster 4: Back-Right (45° angle, facing backward-right) -->
  <joint name="thruster4_joint" type="revolute">
    <parent link="base_link" />
    <child link="thruster4" />
    <origin xyz="-0.14 0.092 0" rpy="0 0 2.356194490192345"/>
    <axis xyz="1 0 0" />  <!-- CRITICAL FIX: Changed from "0 0 -1" -->
    <limit lower="-1e+12" upper="1e+12" effort="-1" velocity="-1"/>
  </joint>

  <!-- Thruster 5: Vertical Front (pointing down) -->
  <joint name="thruster5_joint" type="revolute">
    <parent link="base_link" />
    <child link="thruster5" />
    <origin xyz="0 -0.109 0.077" rpy="0 0 0"/>
    <axis xyz="0 0 1" />  <!-- This one is correct -->
    <limit lower="-1e+12" upper="1e+12" effort="-1" velocity="-1"/>
  </joint>

  <!-- Thruster 6: Vertical Back (pointing down) -->
  <joint name="thruster6_joint" type="revolute">
    <parent link="base_link" />
    <child link="thruster6" />
    <origin xyz="0 0.109 0.077" rpy="0 0 0"/>
    <axis xyz="0 0 1" />  <!-- This one is correct -->
    <limit lower="-1e+12" upper="1e+12" effort="-1" velocity="-1"/>
  </joint>

    <gazebo>
    <plugin
        filename="ignition-gazebo-thruster-system"
        name="ignition::gazebo::systems::Thruster">
      <namespace>orca4_ign</namespace>
      <joint_name>thruster1_joint</joint_name>
      <thrust_coefficient>0.02</thrust_coefficient>
      <fluid_density>1000</fluid_density>
      <propeller_diameter>0.1</propeller_diameter>
      <velocity_control>true</velocity_control>
      <use_angvel_cmd>True</use_angvel_cmd>
    </plugin>
    </gazebo>

    <gazebo>
    <plugin
        filename="ignition-gazebo-thruster-system"
        name="ignition::gazebo::systems::Thruster">
      <namespace>orca4_ign</namespace>
      <joint_name>thruster2_joint</joint_name>
      <thrust_coefficient>0.02</thrust_coefficient>
      <fluid_density>1000</fluid_density>
      <propeller_diameter>0.1</propeller_diameter>
      <velocity_control>true</velocity_control>
      <use_angvel_cmd>True</use_angvel_cmd>
    </plugin>
    </gazebo>

    <gazebo>
    <plugin
        filename="ignition-gazebo-thruster-system"
        name="ignition::gazebo::systems::Thruster">
      <namespace>orca4_ign</namespace>
      <joint_name>thruster3_joint</joint_name>
      <!-- Reverse spin to balance torque -->
      <thrust_coefficient>-0.02</thrust_coefficient>
      <fluid_density>1000</fluid_density>
      <propeller_diameter>0.1</propeller_diameter>
      <velocity_control>true</velocity_control>
      <use_angvel_cmd>True</use_angvel_cmd>
    </plugin>
    </gazebo>

    <gazebo>
    <plugin
        filename="ignition-gazebo-thruster-system"
        name="ignition::gazebo::systems::Thruster">
      <namespace>orca4_ign</namespace>
      <joint_name>thruster4_joint</joint_name>
      <!-- Reverse spin to balance torque -->
      <thrust_coefficient>-0.02</thrust_coefficient>
      <fluid_density>1000</fluid_density>
      <propeller_diameter>0.1</propeller_diameter>
      <velocity_control>true</velocity_control>
      <use_angvel_cmd>True</use_angvel_cmd>
    </plugin>
    </gazebo>

    <gazebo>
    <plugin
        filename="ignition-gazebo-thruster-system"
        name="ignition::gazebo::systems::Thruster">
      <namespace>orca4_ign</namespace>
      <joint_name>thruster5_joint</joint_name>
      <thrust_coefficient>0.02</thrust_coefficient>
      <fluid_density>1000</fluid_density>
      <propeller_diameter>0.1</propeller_diameter>
      <velocity_control>true</velocity_control>
      <use_angvel_cmd>True</use_angvel_cmd>
    </plugin>
    </gazebo>

    <gazebo>
    <plugin
        filename="ignition-gazebo-thruster-system"
        name="ignition::gazebo::systems::Thruster">
      <namespace>orca4_ign</namespace>
      <joint_name>thruster6_joint</joint_name>
      <!-- Reverse spin to balance torque -->
      <thrust_coefficient>-0.02</thrust_coefficient>
      <fluid_density>1000</fluid_density>
      <propeller_diameter>0.1</propeller_diameter>
      <velocity_control>true</velocity_control>
      <use_angvel_cmd>True</use_angvel_cmd>
    </plugin>
    </gazebo>
    

    <link name="front_left_cam_link">
    <visual>
      <geometry><box size="0.02 0.02 0.02"/></geometry>
      <material name="red"><color rgba="1 0 0 1"/></material>
    </visual>
    <inertial>
      <mass value="0.001"/>
      <inertia ixx="0.0001" ixy="0" ixz="0" iyy="0.0001" iyz="0" izz="0.0001"/>
    </inertial>
  </link>

  <joint name="front_left_cam_joint" type="fixed">
    <parent link="base_link"/>
    <child link="front_left_cam_link"/>
    <origin xyz="0.24 0.08 0" rpy="0 0 0"/>
  </joint>

  <link name="front_right_cam_link">
    <visual>
      <geometry><box size="0.02 0.02 0.02"/></geometry>
      <material name="red"><color rgba="1 0 0 1"/></material>
    </visual>
    <inertial>
      <mass value="0.001"/>
      <inertia ixx="0.0001" ixy="0" ixz="0" iyy="0.0001" iyz="0" izz="0.0001"/>
    </inertial>
  </link>

  <joint name="front_right_cam_joint" type="fixed">
    <parent link="base_link"/>
    <child link="front_right_cam_link"/>
    <origin xyz="0.24 -0.08 0" rpy="0 0 0"/>
  </joint>

  <link name="bottom_cam_link">
    <visual>
      <geometry><box size="0.02 0.02 0.02"/></geometry>
      <material name="green"><color rgba="0 1 0 1"/></material>
    </visual>
    <inertial>
      <mass value="0.001"/>
      <inertia ixx="0.0001" ixy="0" ixz="0" iyy="0.0001" iyz="0" izz="0.0001"/>
    </inertial>
  </link>

  <joint name="bottom_cam_joint" type="fixed">
    <parent link="base_link"/>
    <child link="bottom_cam_link"/>
    <origin xyz="0.1 0 -0.05" rpy="0 1.570796 0"/>
  </joint>

  <link name="back_cam_link">
    <visual>
      <geometry><box size="0.02 0.02 0.02"/></geometry>
      <material name="blue"><color rgba="0 0 1 1"/></material>
    </visual>
    <inertial>
      <mass value="0.001"/>
      <inertia ixx="0.0001" ixy="0" ixz="0" iyy="0.0001" iyz="0" izz="0.0001"/>
    </inertial>
  </link>

  <joint name="back_cam_joint" type="fixed">
    <parent link="base_link"/>
    <child link="back_cam_link"/>
    <origin xyz="-0.24 0 0" rpy="0 0 3.141592"/>
  </joint>
    <gazebo reference="front_left_cam_link">
    <sensor name="front_left_camera" type="camera">
      <camera>
        <horizontal_fov>1.309</horizontal_fov>
        <image>
          <width>1280</width>
          <height>720</height>
        </image>
        <clip>
          <near>0.1</near>
          <far>30</far>
        </clip>
      </camera>
      <always_on>1</always_on>
      <update_rate>30</update_rate>
      <visualize>true</visualize>
      <topic>/front_left/image_raw</topic>
    </sensor>
  </gazebo>

  <gazebo reference="front_right_cam_link">
    <sensor name="front_right_camera" type="camera">
      <camera>
        <horizontal_fov>1.309</horizontal_fov>
        <image>
          <width>1280</width>
          <height>720</height>
        </image>
        <clip>
          <near>0.1</near>
          <far>30</far>
        </clip>
      </camera>
      <always_on>1</always_on>
      <update_rate>30</update_rate>
      <visualize>true</visualize>
      <topic>/front_right/image_raw</topic>
    </sensor>
  </gazebo>

  <gazebo reference="bottom_cam_link">
    <sensor name="bottom_camera" type="camera">
      <camera>
        <horizontal_fov>1.955</horizontal_fov>
        <image>
          <width>1280</width>
          <height>720</height>
        </image>
        <clip>
          <near>0.1</near>
          <far>30</far>
        </clip>
      </camera>
      <always_on>1</always_on>
      <update_rate>30</update_rate>
      <visualize>true</visualize>
      <topic>/bottom/image_raw</topic>
    </sensor>
  </gazebo>

  <gazebo reference="back_cam_link">
    <sensor name="back_camera" type="camera">
      <camera>
        <horizontal_fov>1.309</horizontal_fov>
        <image>
          <width>640</width>
          <height>480</height>
        </image>
        <clip>
          <near>0.1</near>
          <far>30</far>
        </clip>
      </camera>
      <always_on>1</always_on>
      <update_rate>30</update_rate>
      <visualize>true</visualize>
      <topic>/back/image_raw</topic>
    </sensor>
  </gazebo>

    <gazebo>
    <plugin
    filename="ignition-gazebo-odometry-publisher-system"
    name="ignition::gazebo::systems::OdometryPublisher">
    <link_name>base_link</link_name>  <!-- Use your main body link -->
    <odom_publish_topic>/odom</odom_publish_topic> <!-- Optional -->
    <frame_id>odom</frame_id>
    <child_frame_id>base_link</child_frame_id>
    <publish_tf>true</publish_tf>
    <use_world_coordinates>true</use_world_coordinates>
    <covariance> <!-- Optional -->
      0.01 0 0 0 0 0
      0 0.01 0 0 0 0
      0 0 0.01 0 0 0
      0 0 0 0.01 0 0
      0 0 0 0 0.01 0
      0 0 0 0 0 0.01
    </covariance>
  </plugin>
  </gazebo>

    <link name="imu_link">
      <visual name="imu_visual">
        <geometry>
          <box>
          <size>0.1 0.1 0.1</size>
          </box>
        </geometry>
      </visual>

      <collision name="imu_collision">
        <geometry>
          <box>
          <size>0.1 0.1 0.1</size>
          </box>
        </geometry>
      </collision>

      <inertial>
        <pose>0 0 0 3.141592653589793 0 0</pose>
        <mass value="0.001"/>
        <inertia>
          <ixx>0.001</ixx>
          <ixy>0</ixy>
          <ixz>0</ixz>
          <iyy>0.001</iyy>
          <iyz>0</iyz>
          <izz>0.001</izz>
        </inertia>
      </inertial>
    </link>


  <joint name="imu_joint" type="fixed">
    <parent link="base_link"/>
    <child link="imu_link"/>
    <origin xyz="0 0 0.01"/>
  </joint>


  <gazebo reference="imu_link">
  <sensor name="imu_sensor" type="imu">
        <ignition_frame_id>imu_link</ignition_frame_id>
        <plugin filename="ignition-gazebo-imu-system" name="ignition::gazebo::systems::Imu">
        </plugin>

        <topic>/demo/imu</topic>
        <always_on>true</always_on>
        <update_rate>100</update_rate>
        <visualize>true</visualize>
        <enable_metrics>true</enable_metrics>
        <imu>
          <angular_velocity>
            <x>
              <noise type="gaussian">
                <mean>0.0</mean>
                <stddev>2e-4</stddev>
                <bias_mean>0.0000075</bias_mean>
                <bias_stddev>0.0000008</bias_stddev>
              </noise>
            </x>
            <y>
              <noise type="gaussian">
                <mean>0.0</mean>
                <stddev>2e-4</stddev>
                <bias_mean>0.0000075</bias_mean>
                <bias_stddev>0.0000008</bias_stddev>
              </noise>
            </y>
            <z>
              <noise type="gaussian">
                <mean>0.0</mean>
                <stddev>2e-4</stddev>
                <bias_mean>0.0000075</bias_mean>
                <bias_stddev>0.0000008</bias_stddev>
              </noise>
            </z>
          </angular_velocity>
          <linear_acceleration>
            <x>
              <noise type="gaussian">
                <mean>0.0</mean>
                <stddev>1.7e-2</stddev>
                <bias_mean>0.1</bias_mean>
                <bias_stddev>0.001</bias_stddev>
              </noise>
            </x>
            <y>
              <noise type="gaussian">
                <mean>0.0</mean>
                <stddev>1.7e-2</stddev>
                <bias_mean>0.1</bias_mean>
                <bias_stddev>0.001</bias_stddev>
              </noise>
            </y>
            <z>
              <noise type="gaussian">
                <mean>0.0</mean>
                <stddev>1.7e-2</stddev>
                <bias_mean>0.1</bias_mean>
                <bias_stddev>0.001</bias_stddev>
              </noise>
            </z>
          </linear_acceleration>
          <frame_id>imu_link</frame_id>
        </imu>
      </sensor>
  </gazebo>

</robot>